Workbook

Sheet Harbor Bay assumptions
A1: Harbor Bay assumptions
A2: Atlas Commerce — Harbor Bay · Base
A4: Variable / dimension | B4: Harbor Bay
A5: Monthly visits | B5: =50000 -> 50000
A6: Conversion rate | B6: =0.025 -> 0.025
A7: Average order value | B7: =85 -> 85
A8: Product cost per order (provisional) | B8: ='Harbor Bay assumptions'!B7*'Catalog product-cost estimation'!B7 -> 42.774903
A9: Fulfillment cost per order | B9: =12 -> 12
A10: Campaign spend per month | B10: =15000 -> 15000
A11: Inference cost per month | B11: =3000 -> 3000
A12: Infrastructure cost per month (synthetic demo) | B12: =500 -> 500
A13: Opening cash (synthetic demo) | B13: =30000 -> 30000

Sheet Harbor Bay monthly P&L and cash
A1: Harbor Bay monthly P&L and cash
A2: Atlas Commerce — Harbor Bay · Base
A4: Variable / dimension | B4: 2026-10 | C4: 2026-11 | D4: 2026-12 | E4: 2027-01 | F4: 2027-02 | G4: 2027-03 | H4: 2027-04 | I4: 2027-05 | J4: 2027-06 | K4: 2027-07 | L4: 2027-08 | M4: 2027-09 | N4: 2027-10 | O4: 2027-11 | P4: 2027-12
A5: Visits | B5: =SUM('Harbor Bay monthly P&L and cash'!B6) -> 50000 | C5: =SUM('Harbor Bay monthly P&L and cash'!C6) -> 50000 | D5: =SUM('Harbor Bay monthly P&L and cash'!D6) -> 50000 | E5: =SUM('Harbor Bay monthly P&L and cash'!E6) -> 50000 | F5: =SUM('Harbor Bay monthly P&L and cash'!F6) -> 50000 | G5: =SUM('Harbor Bay monthly P&L and cash'!G6) -> 50000 | H5: =SUM('Harbor Bay monthly P&L and cash'!H6) -> 50000 | I5: =SUM('Harbor Bay monthly P&L and cash'!I6) -> 50000 | ... P5: =SUM('Harbor Bay monthly P&L and cash'!P6) -> 50000
A6: Harbor Bay | B6: =IF('Harbor Bay assumptions'!B5="","",'Harbor Bay assumptions'!B5) -> 50000 | C6: =IF('Harbor Bay assumptions'!B5="","",'Harbor Bay assumptions'!B5) -> 50000 | D6: =IF('Harbor Bay assumptions'!B5="","",'Harbor Bay assumptions'!B5) -> 50000 | E6: =IF('Harbor Bay assumptions'!B5="","",'Harbor Bay assumptions'!B5) -> 50000 | F6: =IF('Harbor Bay assumptions'!B5="","",'Harbor Bay assumptions'!B5) -> 50000 | G6: =IF('Harbor Bay assumptions'!B5="","",'Harbor Bay assumptions'!B5) -> 50000 | H6: =IF('Harbor Bay assumptions'!B5="","",'Harbor Bay assumptions'!B5) -> 50000 | I6: =IF('Harbor Bay assumptions'!B5="","",'Harbor Bay assumptions'!B5) -> 50000 | J6: =IF('Harbor Bay assumptions'!B5="","",'Harbor Bay assumptions'!B5) -> 50000 | K6: =IF('Harbor Bay assumptions'!B5="","",'Harbor Bay assumptions'!B5) -> 50000 | L6: =IF('Harbor Bay assumptions'!B5="","",'Harbor Bay assumptions'!B5) -> 50000 | M6: =IF('Harbor Bay assumptions'!B5="","",'Harbor Bay assumptions'!B5) -> 50000 | N6: =IF('Harbor Bay assumptions'!B5="","",'Harbor Bay assumptions'!B5) -> 50000 | O6: =IF('Harbor Bay assumptions'!B5="","",'Harbor Bay assumptions'!B5) -> 50000 | P6: =IF('Harbor Bay assumptions'!B5="","",'Harbor Bay assumptions'!B5) -> 50000
A7: Orders | B7: =SUM('Harbor Bay monthly P&L and cash'!B8) -> 1250 | C7: =SUM('Harbor Bay monthly P&L and cash'!C8) -> 1250 | D7: =SUM('Harbor Bay monthly P&L and cash'!D8) -> 1250 | E7: =SUM('Harbor Bay monthly P&L and cash'!E8) -> 1250 | F7: =SUM('Harbor Bay monthly P&L and cash'!F8) -> 1250 | G7: =SUM('Harbor Bay monthly P&L and cash'!G8) -> 1250 | H7: =SUM('Harbor Bay monthly P&L and cash'!H8) -> 1250 | I7: =SUM('Harbor Bay monthly P&L and cash'!I8) -> 1250 | ... P7: =SUM('Harbor Bay monthly P&L and cash'!P8) -> 1250
A8: Harbor Bay | B8: ='Harbor Bay monthly P&L and cash'!B6*'Harbor Bay assumptions'!B6 -> 1250 | C8: ='Harbor Bay monthly P&L and cash'!C6*'Harbor Bay assumptions'!B6 -> 1250 | D8: ='Harbor Bay monthly P&L and cash'!D6*'Harbor Bay assumptions'!B6 -> 1250 | E8: ='Harbor Bay monthly P&L and cash'!E6*'Harbor Bay assumptions'!B6 -> 1250 | F8: ='Harbor Bay monthly P&L and cash'!F6*'Harbor Bay assumptions'!B6 -> 1250 | G8: ='Harbor Bay monthly P&L and cash'!G6*'Harbor Bay assumptions'!B6 -> 1250 | H8: ='Harbor Bay monthly P&L and cash'!H6*'Harbor Bay assumptions'!B6 -> 1250 | I8: ='Harbor Bay monthly P&L and cash'!I6*'Harbor Bay assumptions'!B6 -> 1250 | J8: ='Harbor Bay monthly P&L and cash'!J6*'Harbor Bay assumptions'!B6 -> 1250 | K8: ='Harbor Bay monthly P&L and cash'!K6*'Harbor Bay assumptions'!B6 -> 1250 | L8: ='Harbor Bay monthly P&L and cash'!L6*'Harbor Bay assumptions'!B6 -> 1250 | M8: ='Harbor Bay monthly P&L and cash'!M6*'Harbor Bay assumptions'!B6 -> 1250 | N8: ='Harbor Bay monthly P&L and cash'!N6*'Harbor Bay assumptions'!B6 -> 1250 | O8: ='Harbor Bay monthly P&L and cash'!O6*'Harbor Bay assumptions'!B6 -> 1250 | P8: ='Harbor Bay monthly P&L and cash'!P6*'Harbor Bay assumptions'!B6 -> 1250
A9: Revenue | B9: =SUM('Harbor Bay monthly P&L and cash'!B10) -> 106250 | C9: =SUM('Harbor Bay monthly P&L and cash'!C10) -> 106250 | D9: =SUM('Harbor Bay monthly P&L and cash'!D10) -> 106250 | E9: =SUM('Harbor Bay monthly P&L and cash'!E10) -> 106250 | F9: =SUM('Harbor Bay monthly P&L and cash'!F10) -> 106250 | G9: =SUM('Harbor Bay monthly P&L and cash'!G10) -> 106250 | H9: =SUM('Harbor Bay monthly P&L and cash'!H10) -> 106250 | I9: =SUM('Harbor Bay monthly P&L and cash'!I10) -> 106250 | ... P9: =SUM('Harbor Bay monthly P&L and cash'!P10) -> 106250
A10: Harbor Bay | B10: ='Harbor Bay monthly P&L and cash'!B8*'Harbor Bay assumptions'!B7 -> 106250 | C10: ='Harbor Bay monthly P&L and cash'!C8*'Harbor Bay assumptions'!B7 -> 106250 | D10: ='Harbor Bay monthly P&L and cash'!D8*'Harbor Bay assumptions'!B7 -> 106250 | E10: ='Harbor Bay monthly P&L and cash'!E8*'Harbor Bay assumptions'!B7 -> 106250 | F10: ='Harbor Bay monthly P&L and cash'!F8*'Harbor Bay assumptions'!B7 -> 106250 | G10: ='Harbor Bay monthly P&L and cash'!G8*'Harbor Bay assumptions'!B7 -> 106250 | H10: ='Harbor Bay monthly P&L and cash'!H8*'Harbor Bay assumptions'!B7 -> 106250 | I10: ='Harbor Bay monthly P&L and cash'!I8*'Harbor Bay assumptions'!B7 -> 106250 | J10: ='Harbor Bay monthly P&L and cash'!J8*'Harbor Bay assumptions'!B7 -> 106250 | K10: ='Harbor Bay monthly P&L and cash'!K8*'Harbor Bay assumptions'!B7 -> 106250 | L10: ='Harbor Bay monthly P&L and cash'!L8*'Harbor Bay assumptions'!B7 -> 106250 | M10: ='Harbor Bay monthly P&L and cash'!M8*'Harbor Bay assumptions'!B7 -> 106250 | N10: ='Harbor Bay monthly P&L and cash'!N8*'Harbor Bay assumptions'!B7 -> 106250 | O10: ='Harbor Bay monthly P&L and cash'!O8*'Harbor Bay assumptions'!B7 -> 106250 | P10: ='Harbor Bay monthly P&L and cash'!P8*'Harbor Bay assumptions'!B7 -> 106250
A11: Product cost | B11: =SUM('Harbor Bay monthly P&L and cash'!B12) -> 53468.629 | C11: =SUM('Harbor Bay monthly P&L and cash'!C12) -> 53468.629 | D11: =SUM('Harbor Bay monthly P&L and cash'!D12) -> 53468.629 | E11: =SUM('Harbor Bay monthly P&L and cash'!E12) -> 53468.629 | F11: =SUM('Harbor Bay monthly P&L and cash'!F12) -> 53468.629 | G11: =SUM('Harbor Bay monthly P&L and cash'!G12) -> 53468.629 | H11: =SUM('Harbor Bay monthly P&L and cash'!H12) -> 53468.629 | I11: =SUM('Harbor Bay monthly P&L and cash'!I12) -> 53468.629 | ... P11: =SUM('Harbor Bay monthly P&L and cash'!P12) -> 53468.629
A12: Harbor Bay | B12: ='Harbor Bay monthly P&L and cash'!B8*'Harbor Bay assumptions'!B8 -> 53468.629 | C12: ='Harbor Bay monthly P&L and cash'!C8*'Harbor Bay assumptions'!B8 -> 53468.629 | D12: ='Harbor Bay monthly P&L and cash'!D8*'Harbor Bay assumptions'!B8 -> 53468.629 | E12: ='Harbor Bay monthly P&L and cash'!E8*'Harbor Bay assumptions'!B8 -> 53468.629 | F12: ='Harbor Bay monthly P&L and cash'!F8*'Harbor Bay assumptions'!B8 -> 53468.629 | G12: ='Harbor Bay monthly P&L and cash'!G8*'Harbor Bay assumptions'!B8 -> 53468.629 | H12: ='Harbor Bay monthly P&L and cash'!H8*'Harbor Bay assumptions'!B8 -> 53468.629 | I12: ='Harbor Bay monthly P&L and cash'!I8*'Harbor Bay assumptions'!B8 -> 53468.629 | J12: ='Harbor Bay monthly P&L and cash'!J8*'Harbor Bay assumptions'!B8 -> 53468.629 | K12: ='Harbor Bay monthly P&L and cash'!K8*'Harbor Bay assumptions'!B8 -> 53468.629 | L12: ='Harbor Bay monthly P&L and cash'!L8*'Harbor Bay assumptions'!B8 -> 53468.629 | M12: ='Harbor Bay monthly P&L and cash'!M8*'Harbor Bay assumptions'!B8 -> 53468.629 | N12: ='Harbor Bay monthly P&L and cash'!N8*'Harbor Bay assumptions'!B8 -> 53468.629 | O12: ='Harbor Bay monthly P&L and cash'!O8*'Harbor Bay assumptions'!B8 -> 53468.629 | P12: ='Harbor Bay monthly P&L and cash'!P8*'Harbor Bay assumptions'!B8 -> 53468.629
A13: Fulfillment cost | B13: =SUM('Harbor Bay monthly P&L and cash'!B14) -> 15000 | C13: =SUM('Harbor Bay monthly P&L and cash'!C14) -> 15000 | D13: =SUM('Harbor Bay monthly P&L and cash'!D14) -> 15000 | E13: =SUM('Harbor Bay monthly P&L and cash'!E14) -> 15000 | F13: =SUM('Harbor Bay monthly P&L and cash'!F14) -> 15000 | G13: =SUM('Harbor Bay monthly P&L and cash'!G14) -> 15000 | H13: =SUM('Harbor Bay monthly P&L and cash'!H14) -> 15000 | I13: =SUM('Harbor Bay monthly P&L and cash'!I14) -> 15000 | ... P13: =SUM('Harbor Bay monthly P&L and cash'!P14) -> 15000
A14: Harbor Bay | B14: ='Harbor Bay monthly P&L and cash'!B8*'Harbor Bay assumptions'!B9 -> 15000 | C14: ='Harbor Bay monthly P&L and cash'!C8*'Harbor Bay assumptions'!B9 -> 15000 | D14: ='Harbor Bay monthly P&L and cash'!D8*'Harbor Bay assumptions'!B9 -> 15000 | E14: ='Harbor Bay monthly P&L and cash'!E8*'Harbor Bay assumptions'!B9 -> 15000 | F14: ='Harbor Bay monthly P&L and cash'!F8*'Harbor Bay assumptions'!B9 -> 15000 | G14: ='Harbor Bay monthly P&L and cash'!G8*'Harbor Bay assumptions'!B9 -> 15000 | H14: ='Harbor Bay monthly P&L and cash'!H8*'Harbor Bay assumptions'!B9 -> 15000 | I14: ='Harbor Bay monthly P&L and cash'!I8*'Harbor Bay assumptions'!B9 -> 15000 | J14: ='Harbor Bay monthly P&L and cash'!J8*'Harbor Bay assumptions'!B9 -> 15000 | K14: ='Harbor Bay monthly P&L and cash'!K8*'Harbor Bay assumptions'!B9 -> 15000 | L14: ='Harbor Bay monthly P&L and cash'!L8*'Harbor Bay assumptions'!B9 -> 15000 | M14: ='Harbor Bay monthly P&L and cash'!M8*'Harbor Bay assumptions'!B9 -> 15000 | N14: ='Harbor Bay monthly P&L and cash'!N8*'Harbor Bay assumptions'!B9 -> 15000 | O14: ='Harbor Bay monthly P&L and cash'!O8*'Harbor Bay assumptions'!B9 -> 15000 | P14: ='Harbor Bay monthly P&L and cash'!P8*'Harbor Bay assumptions'!B9 -> 15000
A15: Gross profit | B15: =SUM('Harbor Bay monthly P&L and cash'!B16) -> 37781.371 | C15: =SUM('Harbor Bay monthly P&L and cash'!C16) -> 37781.371 | D15: =SUM('Harbor Bay monthly P&L and cash'!D16) -> 37781.371 | E15: =SUM('Harbor Bay monthly P&L and cash'!E16) -> 37781.371 | F15: =SUM('Harbor Bay monthly P&L and cash'!F16) -> 37781.371 | G15: =SUM('Harbor Bay monthly P&L and cash'!G16) -> 37781.371 | H15: =SUM('Harbor Bay monthly P&L and cash'!H16) -> 37781.371 | I15: =SUM('Harbor Bay monthly P&L and cash'!I16) -> 37781.371 | ... P15: =SUM('Harbor Bay monthly P&L and cash'!P16) -> 37781.371
A16: Harbor Bay | B16: ='Harbor Bay monthly P&L and cash'!B10-'Harbor Bay monthly P&L and cash'!B12-'Harbor Bay monthly P&L and cash'!B14 -> 37781.371 | C16: ='Harbor Bay monthly P&L and cash'!C10-'Harbor Bay monthly P&L and cash'!C12-'Harbor Bay monthly P&L and cash'!C14 -> 37781.371 | D16: ='Harbor Bay monthly P&L and cash'!D10-'Harbor Bay monthly P&L and cash'!D12-'Harbor Bay monthly P&L and cash'!D14 -> 37781.371 | E16: ='Harbor Bay monthly P&L and cash'!E10-'Harbor Bay monthly P&L and cash'!E12-'Harbor Bay monthly P&L and cash'!E14 -> 37781.371 | F16: ='Harbor Bay monthly P&L and cash'!F10-'Harbor Bay monthly P&L and cash'!F12-'Harbor Bay monthly P&L and cash'!F14 -> 37781.371 | G16: ='Harbor Bay monthly P&L and cash'!G10-'Harbor Bay monthly P&L and cash'!G12-'Harbor Bay monthly P&L and cash'!G14 -> 37781.371 | H16: ='Harbor Bay monthly P&L and cash'!H10-'Harbor Bay monthly P&L and cash'!H12-'Harbor Bay monthly P&L and cash'!H14 -> 37781.371 | I16: ='Harbor Bay monthly P&L and cash'!I10-'Harbor Bay monthly P&L and cash'!I12-'Harbor Bay monthly P&L and cash'!I14 -> 37781.371 | ... P16: ='Harbor Bay monthly P&L and cash'!P10-'Harbor Bay monthly P&L and cash'!P12-'Harbor Bay monthly P&L and cash'!P14 -> 37781.371
A17: Gross margin | B17: =IFERROR('Harbor Bay monthly P&L and cash'!B15/'Harbor Bay monthly P&L and cash'!B9,"") -> 0.35558938 | C17: =IFERROR('Harbor Bay monthly P&L and cash'!C15/'Harbor Bay monthly P&L and cash'!C9,"") -> 0.35558938 | D17: =IFERROR('Harbor Bay monthly P&L and cash'!D15/'Harbor Bay monthly P&L and cash'!D9,"") -> 0.35558938 | E17: =IFERROR('Harbor Bay monthly P&L and cash'!E15/'Harbor Bay monthly P&L and cash'!E9,"") -> 0.35558938 | F17: =IFERROR('Harbor Bay monthly P&L and cash'!F15/'Harbor Bay monthly P&L and cash'!F9,"") -> 0.35558938 | G17: =IFERROR('Harbor Bay monthly P&L and cash'!G15/'Harbor Bay monthly P&L and cash'!G9,"") -> 0.35558938 | H17: =IFERROR('Harbor Bay monthly P&L and cash'!H15/'Harbor Bay monthly P&L and cash'!H9,"") -> 0.35558938 | I17: =IFERROR('Harbor Bay monthly P&L and cash'!I15/'Harbor Bay monthly P&L and cash'!I9,"") -> 0.35558938 | ... P17: =IFERROR('Harbor Bay monthly P&L and cash'!P15/'Harbor Bay monthly P&L and cash'!P9,"") -> 0.35558938
A18: Harbor Bay | B18: =IFERROR('Harbor Bay monthly P&L and cash'!B16/'Harbor Bay monthly P&L and cash'!B10,"") -> 0.35558938 | C18: =IFERROR('Harbor Bay monthly P&L and cash'!C16/'Harbor Bay monthly P&L and cash'!C10,"") -> 0.35558938 | D18: =IFERROR('Harbor Bay monthly P&L and cash'!D16/'Harbor Bay monthly P&L and cash'!D10,"") -> 0.35558938 | E18: =IFERROR('Harbor Bay monthly P&L and cash'!E16/'Harbor Bay monthly P&L and cash'!E10,"") -> 0.35558938 | F18: =IFERROR('Harbor Bay monthly P&L and cash'!F16/'Harbor Bay monthly P&L and cash'!F10,"") -> 0.35558938 | G18: =IFERROR('Harbor Bay monthly P&L and cash'!G16/'Harbor Bay monthly P&L and cash'!G10,"") -> 0.35558938 | H18: =IFERROR('Harbor Bay monthly P&L and cash'!H16/'Harbor Bay monthly P&L and cash'!H10,"") -> 0.35558938 | I18: =IFERROR('Harbor Bay monthly P&L and cash'!I16/'Harbor Bay monthly P&L and cash'!I10,"") -> 0.35558938 | ... P18: =IFERROR('Harbor Bay monthly P&L and cash'!P16/'Harbor Bay monthly P&L and cash'!P10,"") -> 0.35558938
A19: Campaign expense | B19: =SUM('Harbor Bay monthly P&L and cash'!B20) -> 15000 | C19: =SUM('Harbor Bay monthly P&L and cash'!C20) -> 15000 | D19: =SUM('Harbor Bay monthly P&L and cash'!D20) -> 15000 | E19: =SUM('Harbor Bay monthly P&L and cash'!E20) -> 15000 | F19: =SUM('Harbor Bay monthly P&L and cash'!F20) -> 15000 | G19: =SUM('Harbor Bay monthly P&L and cash'!G20) -> 15000 | H19: =SUM('Harbor Bay monthly P&L and cash'!H20) -> 15000 | I19: =SUM('Harbor Bay monthly P&L and cash'!I20) -> 15000 | ... P19: =SUM('Harbor Bay monthly P&L and cash'!P20) -> 15000
A20: Harbor Bay | B20: =IF('Harbor Bay assumptions'!B10="","",'Harbor Bay assumptions'!B10) -> 15000 | C20: =IF('Harbor Bay assumptions'!B10="","",'Harbor Bay assumptions'!B10) -> 15000 | D20: =IF('Harbor Bay assumptions'!B10="","",'Harbor Bay assumptions'!B10) -> 15000 | E20: =IF('Harbor Bay assumptions'!B10="","",'Harbor Bay assumptions'!B10) -> 15000 | F20: =IF('Harbor Bay assumptions'!B10="","",'Harbor Bay assumptions'!B10) -> 15000 | G20: =IF('Harbor Bay assumptions'!B10="","",'Harbor Bay assumptions'!B10) -> 15000 | H20: =IF('Harbor Bay assumptions'!B10="","",'Harbor Bay assumptions'!B10) -> 15000 | I20: =IF('Harbor Bay assumptions'!B10="","",'Harbor Bay assumptions'!B10) -> 15000 | J20: =IF('Harbor Bay assumptions'!B10="","",'Harbor Bay assumptions'!B10) -> 15000 | K20: =IF('Harbor Bay assumptions'!B10="","",'Harbor Bay assumptions'!B10) -> 15000 | L20: =IF('Harbor Bay assumptions'!B10="","",'Harbor Bay assumptions'!B10) -> 15000 | M20: =IF('Harbor Bay assumptions'!B10="","",'Harbor Bay assumptions'!B10) -> 15000 | N20: =IF('Harbor Bay assumptions'!B10="","",'Harbor Bay assumptions'!B10) -> 15000 | O20: =IF('Harbor Bay assumptions'!B10="","",'Harbor Bay assumptions'!B10) -> 15000 | P20: =IF('Harbor Bay assumptions'!B10="","",'Harbor Bay assumptions'!B10) -> 15000
A21: Inference expense | B21: =SUM('Harbor Bay monthly P&L and cash'!B22) -> 3000 | C21: =SUM('Harbor Bay monthly P&L and cash'!C22) -> 3000 | D21: =SUM('Harbor Bay monthly P&L and cash'!D22) -> 3000 | E21: =SUM('Harbor Bay monthly P&L and cash'!E22) -> 3000 | F21: =SUM('Harbor Bay monthly P&L and cash'!F22) -> 3000 | G21: =SUM('Harbor Bay monthly P&L and cash'!G22) -> 3000 | H21: =SUM('Harbor Bay monthly P&L and cash'!H22) -> 3000 | I21: =SUM('Harbor Bay monthly P&L and cash'!I22) -> 3000 | ... P21: =SUM('Harbor Bay monthly P&L and cash'!P22) -> 3000
A22: Harbor Bay | B22: =IF('Harbor Bay assumptions'!B11="","",'Harbor Bay assumptions'!B11) -> 3000 | C22: =IF('Harbor Bay assumptions'!B11="","",'Harbor Bay assumptions'!B11) -> 3000 | D22: =IF('Harbor Bay assumptions'!B11="","",'Harbor Bay assumptions'!B11) -> 3000 | E22: =IF('Harbor Bay assumptions'!B11="","",'Harbor Bay assumptions'!B11) -> 3000 | F22: =IF('Harbor Bay assumptions'!B11="","",'Harbor Bay assumptions'!B11) -> 3000 | G22: =IF('Harbor Bay assumptions'!B11="","",'Harbor Bay assumptions'!B11) -> 3000 | H22: =IF('Harbor Bay assumptions'!B11="","",'Harbor Bay assumptions'!B11) -> 3000 | I22: =IF('Harbor Bay assumptions'!B11="","",'Harbor Bay assumptions'!B11) -> 3000 | J22: =IF('Harbor Bay assumptions'!B11="","",'Harbor Bay assumptions'!B11) -> 3000 | K22: =IF('Harbor Bay assumptions'!B11="","",'Harbor Bay assumptions'!B11) -> 3000 | L22: =IF('Harbor Bay assumptions'!B11="","",'Harbor Bay assumptions'!B11) -> 3000 | M22: =IF('Harbor Bay assumptions'!B11="","",'Harbor Bay assumptions'!B11) -> 3000 | N22: =IF('Harbor Bay assumptions'!B11="","",'Harbor Bay assumptions'!B11) -> 3000 | O22: =IF('Harbor Bay assumptions'!B11="","",'Harbor Bay assumptions'!B11) -> 3000 | P22: =IF('Harbor Bay assumptions'!B11="","",'Harbor Bay assumptions'!B11) -> 3000
A23: Infrastructure expense | B23: =IF('Harbor Bay assumptions'!B12="","",'Harbor Bay assumptions'!B12) -> 500 | C23: =IF('Harbor Bay assumptions'!B12="","",'Harbor Bay assumptions'!B12) -> 500 | D23: =IF('Harbor Bay assumptions'!B12="","",'Harbor Bay assumptions'!B12) -> 500 | E23: =IF('Harbor Bay assumptions'!B12="","",'Harbor Bay assumptions'!B12) -> 500 | F23: =IF('Harbor Bay assumptions'!B12="","",'Harbor Bay assumptions'!B12) -> 500 | G23: =IF('Harbor Bay assumptions'!B12="","",'Harbor Bay assumptions'!B12) -> 500 | H23: =IF('Harbor Bay assumptions'!B12="","",'Harbor Bay assumptions'!B12) -> 500 | I23: =IF('Harbor Bay assumptions'!B12="","",'Harbor Bay assumptions'!B12) -> 500 | J23: =IF('Harbor Bay assumptions'!B12="","",'Harbor Bay assumptions'!B12) -> 500 | K23: =IF('Harbor Bay assumptions'!B12="","",'Harbor Bay assumptions'!B12) -> 500 | L23: =IF('Harbor Bay assumptions'!B12="","",'Harbor Bay assumptions'!B12) -> 500 | M23: =IF('Harbor Bay assumptions'!B12="","",'Harbor Bay assumptions'!B12) -> 500 | N23: =IF('Harbor Bay assumptions'!B12="","",'Harbor Bay assumptions'!B12) -> 500 | O23: =IF('Harbor Bay assumptions'!B12="","",'Harbor Bay assumptions'!B12) -> 500 | P23: =IF('Harbor Bay assumptions'!B12="","",'Harbor Bay assumptions'!B12) -> 500
A24: Harbor Bay | B24: =IF('Harbor Bay assumptions'!B12="","",'Harbor Bay assumptions'!B12) -> 500 | C24: =IF('Harbor Bay assumptions'!B12="","",'Harbor Bay assumptions'!B12) -> 500 | D24: =IF('Harbor Bay assumptions'!B12="","",'Harbor Bay assumptions'!B12) -> 500 | E24: =IF('Harbor Bay assumptions'!B12="","",'Harbor Bay assumptions'!B12) -> 500 | F24: =IF('Harbor Bay assumptions'!B12="","",'Harbor Bay assumptions'!B12) -> 500 | G24: =IF('Harbor Bay assumptions'!B12="","",'Harbor Bay assumptions'!B12) -> 500 | H24: =IF('Harbor Bay assumptions'!B12="","",'Harbor Bay assumptions'!B12) -> 500 | I24: =IF('Harbor Bay assumptions'!B12="","",'Harbor Bay assumptions'!B12) -> 500 | J24: =IF('Harbor Bay assumptions'!B12="","",'Harbor Bay assumptions'!B12) -> 500 | K24: =IF('Harbor Bay assumptions'!B12="","",'Harbor Bay assumptions'!B12) -> 500 | L24: =IF('Harbor Bay assumptions'!B12="","",'Harbor Bay assumptions'!B12) -> 500 | M24: =IF('Harbor Bay assumptions'!B12="","",'Harbor Bay assumptions'!B12) -> 500 | N24: =IF('Harbor Bay assumptions'!B12="","",'Harbor Bay assumptions'!B12) -> 500 | O24: =IF('Harbor Bay assumptions'!B12="","",'Harbor Bay assumptions'!B12) -> 500 | P24: =IF('Harbor Bay assumptions'!B12="","",'Harbor Bay assumptions'!B12) -> 500
A25: Contribution | B25: =IF('Harbor Bay monthly P&L and cash'!B23="","",'Harbor Bay monthly P&L and cash'!B15-'Harbor Bay monthly P&L and cash'!B19-'Harbor Bay monthly P&L and cash'!B21-'Harbor Bay monthly P&L and cash'!B23) -> 19281.371 | C25: =IF('Harbor Bay monthly P&L and cash'!C23="","",'Harbor Bay monthly P&L and cash'!C15-'Harbor Bay monthly P&L and cash'!C19-'Harbor Bay monthly P&L and cash'!C21-'Harbor Bay monthly P&L and cash'!C23) -> 19281.371 | D25: =IF('Harbor Bay monthly P&L and cash'!D23="","",'Harbor Bay monthly P&L and cash'!D15-'Harbor Bay monthly P&L and cash'!D19-'Harbor Bay monthly P&L and cash'!D21-'Harbor Bay monthly P&L and cash'!D23) -> 19281.371 | E25: =IF('Harbor Bay monthly P&L and cash'!E23="","",'Harbor Bay monthly P&L and cash'!E15-'Harbor Bay monthly P&L and cash'!E19-'Harbor Bay monthly P&L and cash'!E21-'Harbor Bay monthly P&L and cash'!E23) -> 19281.371 | F25: =IF('Harbor Bay monthly P&L and cash'!F23="","",'Harbor Bay monthly P&L and cash'!F15-'Harbor Bay monthly P&L and cash'!F19-'Harbor Bay monthly P&L and cash'!F21-'Harbor Bay monthly P&L and cash'!F23) -> 19281.371 | G25: =IF('Harbor Bay monthly P&L and cash'!G23="","",'Harbor Bay monthly P&L and cash'!G15-'Harbor Bay monthly P&L and cash'!G19-'Harbor Bay monthly P&L and cash'!G21-'Harbor Bay monthly P&L and cash'!G23) -> 19281.371 | H25: =IF('Harbor Bay monthly P&L and cash'!H23="","",'Harbor Bay monthly P&L and cash'!H15-'Harbor Bay monthly P&L and cash'!H19-'Harbor Bay monthly P&L and cash'!H21-'Harbor Bay monthly P&L and cash'!H23) -> 19281.371 | I25: =IF('Harbor Bay monthly P&L and cash'!I23="","",'Harbor Bay monthly P&L and cash'!I15-'Harbor Bay monthly P&L and cash'!I19-'Harbor Bay monthly P&L and cash'!I21-'Harbor Bay monthly P&L and cash'!I23) -> 19281.371 | ... P25: =IF('Harbor Bay monthly P&L and cash'!P23="","",'Harbor Bay monthly P&L and cash'!P15-'Harbor Bay monthly P&L and cash'!P19-'Harbor Bay monthly P&L and cash'!P21-'Harbor Bay monthly P&L and cash'!P23) -> 19281.371
A26: Harbor Bay | B26: =IF('Harbor Bay monthly P&L and cash'!B24="","",'Harbor Bay monthly P&L and cash'!B16-'Harbor Bay monthly P&L and cash'!B20-'Harbor Bay monthly P&L and cash'!B22-'Harbor Bay monthly P&L and cash'!B24) -> 19281.371 | C26: =IF('Harbor Bay monthly P&L and cash'!C24="","",'Harbor Bay monthly P&L and cash'!C16-'Harbor Bay monthly P&L and cash'!C20-'Harbor Bay monthly P&L and cash'!C22-'Harbor Bay monthly P&L and cash'!C24) -> 19281.371 | D26: =IF('Harbor Bay monthly P&L and cash'!D24="","",'Harbor Bay monthly P&L and cash'!D16-'Harbor Bay monthly P&L and cash'!D20-'Harbor Bay monthly P&L and cash'!D22-'Harbor Bay monthly P&L and cash'!D24) -> 19281.371 | E26: =IF('Harbor Bay monthly P&L and cash'!E24="","",'Harbor Bay monthly P&L and cash'!E16-'Harbor Bay monthly P&L and cash'!E20-'Harbor Bay monthly P&L and cash'!E22-'Harbor Bay monthly P&L and cash'!E24) -> 19281.371 | F26: =IF('Harbor Bay monthly P&L and cash'!F24="","",'Harbor Bay monthly P&L and cash'!F16-'Harbor Bay monthly P&L and cash'!F20-'Harbor Bay monthly P&L and cash'!F22-'Harbor Bay monthly P&L and cash'!F24) -> 19281.371 | G26: =IF('Harbor Bay monthly P&L and cash'!G24="","",'Harbor Bay monthly P&L and cash'!G16-'Harbor Bay monthly P&L and cash'!G20-'Harbor Bay monthly P&L and cash'!G22-'Harbor Bay monthly P&L and cash'!G24) -> 19281.371 | H26: =IF('Harbor Bay monthly P&L and cash'!H24="","",'Harbor Bay monthly P&L and cash'!H16-'Harbor Bay monthly P&L and cash'!H20-'Harbor Bay monthly P&L and cash'!H22-'Harbor Bay monthly P&L and cash'!H24) -> 19281.371 | I26: =IF('Harbor Bay monthly P&L and cash'!I24="","",'Harbor Bay monthly P&L and cash'!I16-'Harbor Bay monthly P&L and cash'!I20-'Harbor Bay monthly P&L and cash'!I22-'Harbor Bay monthly P&L and cash'!I24) -> 19281.371 | ... P26: =IF('Harbor Bay monthly P&L and cash'!P24="","",'Harbor Bay monthly P&L and cash'!P16-'Harbor Bay monthly P&L and cash'!P20-'Harbor Bay monthly P&L and cash'!P22-'Harbor Bay monthly P&L and cash'!P24) -> 19281.371
A27: Contribution margin | B27: =IF('Harbor Bay monthly P&L and cash'!B25="","",IFERROR('Harbor Bay monthly P&L and cash'!B25/'Harbor Bay monthly P&L and cash'!B9,"")) -> 0.18147173 | C27: =IF('Harbor Bay monthly P&L and cash'!C25="","",IFERROR('Harbor Bay monthly P&L and cash'!C25/'Harbor Bay monthly P&L and cash'!C9,"")) -> 0.18147173 | D27: =IF('Harbor Bay monthly P&L and cash'!D25="","",IFERROR('Harbor Bay monthly P&L and cash'!D25/'Harbor Bay monthly P&L and cash'!D9,"")) -> 0.18147173 | E27: =IF('Harbor Bay monthly P&L and cash'!E25="","",IFERROR('Harbor Bay monthly P&L and cash'!E25/'Harbor Bay monthly P&L and cash'!E9,"")) -> 0.18147173 | F27: =IF('Harbor Bay monthly P&L and cash'!F25="","",IFERROR('Harbor Bay monthly P&L and cash'!F25/'Harbor Bay monthly P&L and cash'!F9,"")) -> 0.18147173 | G27: =IF('Harbor Bay monthly P&L and cash'!G25="","",IFERROR('Harbor Bay monthly P&L and cash'!G25/'Harbor Bay monthly P&L and cash'!G9,"")) -> 0.18147173 | H27: =IF('Harbor Bay monthly P&L and cash'!H25="","",IFERROR('Harbor Bay monthly P&L and cash'!H25/'Harbor Bay monthly P&L and cash'!H9,"")) -> 0.18147173 | I27: =IF('Harbor Bay monthly P&L and cash'!I25="","",IFERROR('Harbor Bay monthly P&L and cash'!I25/'Harbor Bay monthly P&L and cash'!I9,"")) -> 0.18147173 | ... P27: =IF('Harbor Bay monthly P&L and cash'!P25="","",IFERROR('Harbor Bay monthly P&L and cash'!P25/'Harbor Bay monthly P&L and cash'!P9,"")) -> 0.18147173
A28: Harbor Bay | B28: =IF('Harbor Bay monthly P&L and cash'!B26="","",IFERROR('Harbor Bay monthly P&L and cash'!B26/'Harbor Bay monthly P&L and cash'!B10,"")) -> 0.18147173 | C28: =IF('Harbor Bay monthly P&L and cash'!C26="","",IFERROR('Harbor Bay monthly P&L and cash'!C26/'Harbor Bay monthly P&L and cash'!C10,"")) -> 0.18147173 | D28: =IF('Harbor Bay monthly P&L and cash'!D26="","",IFERROR('Harbor Bay monthly P&L and cash'!D26/'Harbor Bay monthly P&L and cash'!D10,"")) -> 0.18147173 | E28: =IF('Harbor Bay monthly P&L and cash'!E26="","",IFERROR('Harbor Bay monthly P&L and cash'!E26/'Harbor Bay monthly P&L and cash'!E10,"")) -> 0.18147173 | F28: =IF('Harbor Bay monthly P&L and cash'!F26="","",IFERROR('Harbor Bay monthly P&L and cash'!F26/'Harbor Bay monthly P&L and cash'!F10,"")) -> 0.18147173 | G28: =IF('Harbor Bay monthly P&L and cash'!G26="","",IFERROR('Harbor Bay monthly P&L and cash'!G26/'Harbor Bay monthly P&L and cash'!G10,"")) -> 0.18147173 | H28: =IF('Harbor Bay monthly P&L and cash'!H26="","",IFERROR('Harbor Bay monthly P&L and cash'!H26/'Harbor Bay monthly P&L and cash'!H10,"")) -> 0.18147173 | I28: =IF('Harbor Bay monthly P&L and cash'!I26="","",IFERROR('Harbor Bay monthly P&L and cash'!I26/'Harbor Bay monthly P&L and cash'!I10,"")) -> 0.18147173 | ... P28: =IF('Harbor Bay monthly P&L and cash'!P26="","",IFERROR('Harbor Bay monthly P&L and cash'!P26/'Harbor Bay monthly P&L and cash'!P10,"")) -> 0.18147173
A29: Campaign ROI (proxy, not causal) | B29: =IFERROR(('Harbor Bay monthly P&L and cash'!B15-'Harbor Bay monthly P&L and cash'!B19)/'Harbor Bay monthly P&L and cash'!B19,"") -> 1.5187581 | C29: =IFERROR(('Harbor Bay monthly P&L and cash'!C15-'Harbor Bay monthly P&L and cash'!C19)/'Harbor Bay monthly P&L and cash'!C19,"") -> 1.5187581 | D29: =IFERROR(('Harbor Bay monthly P&L and cash'!D15-'Harbor Bay monthly P&L and cash'!D19)/'Harbor Bay monthly P&L and cash'!D19,"") -> 1.5187581 | E29: =IFERROR(('Harbor Bay monthly P&L and cash'!E15-'Harbor Bay monthly P&L and cash'!E19)/'Harbor Bay monthly P&L and cash'!E19,"") -> 1.5187581 | F29: =IFERROR(('Harbor Bay monthly P&L and cash'!F15-'Harbor Bay monthly P&L and cash'!F19)/'Harbor Bay monthly P&L and cash'!F19,"") -> 1.5187581 | G29: =IFERROR(('Harbor Bay monthly P&L and cash'!G15-'Harbor Bay monthly P&L and cash'!G19)/'Harbor Bay monthly P&L and cash'!G19,"") -> 1.5187581 | H29: =IFERROR(('Harbor Bay monthly P&L and cash'!H15-'Harbor Bay monthly P&L and cash'!H19)/'Harbor Bay monthly P&L and cash'!H19,"") -> 1.5187581 | I29: =IFERROR(('Harbor Bay monthly P&L and cash'!I15-'Harbor Bay monthly P&L and cash'!I19)/'Harbor Bay monthly P&L and cash'!I19,"") -> 1.5187581 | ... P29: =IFERROR(('Harbor Bay monthly P&L and cash'!P15-'Harbor Bay monthly P&L and cash'!P19)/'Harbor Bay monthly P&L and cash'!P19,"") -> 1.5187581
A30: Harbor Bay | B30: =IFERROR(('Harbor Bay monthly P&L and cash'!B16-'Harbor Bay monthly P&L and cash'!B20)/'Harbor Bay monthly P&L and cash'!B20,"") -> 1.5187581 | C30: =IFERROR(('Harbor Bay monthly P&L and cash'!C16-'Harbor Bay monthly P&L and cash'!C20)/'Harbor Bay monthly P&L and cash'!C20,"") -> 1.5187581 | D30: =IFERROR(('Harbor Bay monthly P&L and cash'!D16-'Harbor Bay monthly P&L and cash'!D20)/'Harbor Bay monthly P&L and cash'!D20,"") -> 1.5187581 | E30: =IFERROR(('Harbor Bay monthly P&L and cash'!E16-'Harbor Bay monthly P&L and cash'!E20)/'Harbor Bay monthly P&L and cash'!E20,"") -> 1.5187581 | F30: =IFERROR(('Harbor Bay monthly P&L and cash'!F16-'Harbor Bay monthly P&L and cash'!F20)/'Harbor Bay monthly P&L and cash'!F20,"") -> 1.5187581 | G30: =IFERROR(('Harbor Bay monthly P&L and cash'!G16-'Harbor Bay monthly P&L and cash'!G20)/'Harbor Bay monthly P&L and cash'!G20,"") -> 1.5187581 | H30: =IFERROR(('Harbor Bay monthly P&L and cash'!H16-'Harbor Bay monthly P&L and cash'!H20)/'Harbor Bay monthly P&L and cash'!H20,"") -> 1.5187581 | I30: =IFERROR(('Harbor Bay monthly P&L and cash'!I16-'Harbor Bay monthly P&L and cash'!I20)/'Harbor Bay monthly P&L and cash'!I20,"") -> 1.5187581 | ... P30: =IFERROR(('Harbor Bay monthly P&L and cash'!P16-'Harbor Bay monthly P&L and cash'!P20)/'Harbor Bay monthly P&L and cash'!P20,"") -> 1.5187581
A31: Cash balance | B31: =IF(IF(IF(IFERROR('Harbor Bay assumptions'!B13=""=TRUE,FALSE),TRUE,IF(IFERROR('Harbor Bay monthly P&L and cash'!B25=""=TRUE,FALSE),TRUE,OR('Harbor Bay assumptions'!B13="",'Harbor Bay monthly P&L and cash'!B25="")))="",FALSE,IF(IFERROR('Harbor Bay assumptions'!B13=""=TRUE,FALSE),TRUE,IF(IFERROR('Harbor Bay monthly P&L and cash'!B25=""=TRUE,FALSE),TRUE,OR('Harbor Bay assumptions'!B13="",'Harbor Bay monthly P&L and cash'!B25="")))),"",'Model inputs'!D16+'Harbor Bay monthly P&L and cash'!B25) -> 49281.371 | C31: =IF(IF(IF(IFERROR('Harbor Bay assumptions'!B13=""=TRUE,FALSE),TRUE,IF(IFERROR('Harbor Bay monthly P&L and cash'!C25=""=TRUE,FALSE),TRUE,OR('Harbor Bay assumptions'!B13="",'Harbor Bay monthly P&L and cash'!C25="")))="",FALSE,IF(IFERROR('Harbor Bay assumptions'!B13=""=TRUE,FALSE),TRUE,IF(IFERROR('Harbor Bay monthly P&L and cash'!C25=""=TRUE,FALSE),TRUE,OR('Harbor Bay assumptions'!B13="",'Harbor Bay monthly P&L and cash'!C25="")))),"",'Harbor Bay monthly P&L and cash'!B31+'Harbor Bay monthly P&L and cash'!C25) -> 68562.743 | D31: =IF(IF(IF(IFERROR('Harbor Bay assumptions'!B13=""=TRUE,FALSE),TRUE,IF(IFERROR('Harbor Bay monthly P&L and cash'!D25=""=TRUE,FALSE),TRUE,OR('Harbor Bay assumptions'!B13="",'Harbor Bay monthly P&L and cash'!D25="")))="",FALSE,IF(IFERROR('Harbor Bay assumptions'!B13=""=TRUE,FALSE),TRUE,IF(IFERROR('Harbor Bay monthly P&L and cash'!D25=""=TRUE,FALSE),TRUE,OR('Harbor Bay assumptions'!B13="",'Harbor Bay monthly P&L and cash'!D25="")))),"",'Harbor Bay monthly P&L and cash'!C31+'Harbor Bay monthly P&L and cash'!D25) -> 87844.114 | E31: =IF(IF(IF(IFERROR('Harbor Bay assumptions'!B13=""=TRUE,FALSE),TRUE,IF(IFERROR('Harbor Bay monthly P&L and cash'!E25=""=TRUE,FALSE),TRUE,OR('Harbor Bay assumptions'!B13="",'Harbor Bay monthly P&L and cash'!E25="")))="",FALSE,IF(IFERROR('Harbor Bay assumptions'!B13=""=TRUE,FALSE),TRUE,IF(IFERROR('Harbor Bay monthly P&L and cash'!E25=""=TRUE,FALSE),TRUE,OR('Harbor Bay assumptions'!B13="",'Harbor Bay monthly P&L and cash'!E25="")))),"",'Harbor Bay monthly P&L and cash'!D31+'Harbor Bay monthly P&L and cash'!E25) -> 107125.49 | F31: =IF(IF(IF(IFERROR('Harbor Bay assumptions'!B13=""=TRUE,FALSE),TRUE,IF(IFERROR('Harbor Bay monthly P&L and cash'!F25=""=TRUE,FALSE),TRUE,OR('Harbor Bay assumptions'!B13="",'Harbor Bay monthly P&L and cash'!F25="")))="",FALSE,IF(IFERROR('Harbor Bay assumptions'!B13=""=TRUE,FALSE),TRUE,IF(IFERROR('Harbor Bay monthly P&L and cash'!F25=""=TRUE,FALSE),TRUE,OR('Harbor Bay assumptions'!B13="",'Harbor Bay monthly P&L and cash'!F25="")))),"",'Harbor Bay monthly P&L and cash'!E31+'Harbor Bay monthly P&L and cash'!F25) -> 126406.86 | G31: =IF(IF(IF(IFERROR('Harbor Bay assumptions'!B13=""=TRUE,FALSE),TRUE,IF(IFERROR('Harbor Bay monthly P&L and cash'!G25=""=TRUE,FALSE),TRUE,OR('Harbor Bay assumptions'!B13="",'Harbor Bay monthly P&L and cash'!G25="")))="",FALSE,IF(IFERROR('Harbor Bay assumptions'!B13=""=TRUE,FALSE),TRUE,IF(IFERROR('Harbor Bay monthly P&L and cash'!G25=""=TRUE,FALSE),TRUE,OR('Harbor Bay assumptions'!B13="",'Harbor Bay monthly P&L and cash'!G25="")))),"",'Harbor Bay monthly P&L and cash'!F31+'Harbor Bay monthly P&L and cash'!G25) -> 145688.23 | H31: =IF(IF(IF(IFERROR('Harbor Bay assumptions'!B13=""=TRUE,FALSE),TRUE,IF(IFERROR('Harbor Bay monthly P&L and cash'!H25=""=TRUE,FALSE),TRUE,OR('Harbor Bay assumptions'!B13="",'Harbor Bay monthly P&L and cash'!H25="")))="",FALSE,IF(IFERROR('Harbor Bay assumptions'!B13=""=TRUE,FALSE),TRUE,IF(IFERROR('Harbor Bay monthly P&L and cash'!H25=""=TRUE,FALSE),TRUE,OR('Harbor Bay assumptions'!B13="",'Harbor Bay monthly P&L and cash'!H25="")))),"",'Harbor Bay monthly P&L and cash'!G31+'Harbor Bay monthly P&L and cash'!H25) -> 164969.6 | I31: =IF(IF(IF(IFERROR('Harbor Bay assumptions'!B13=""=TRUE,FALSE),TRUE,IF(IFERROR('Harbor Bay monthly P&L and cash'!I25=""=TRUE,FALSE),TRUE,OR('Harbor Bay assumptions'!B13="",'Harbor Bay monthly P&L and cash'!I25="")))="",FALSE,IF(IFERROR('Harbor Bay assumptions'!B13=""=TRUE,FALSE),TRUE,IF(IFERROR('Harbor Bay monthly P&L and cash'!I25=""=TRUE,FALSE),TRUE,OR('Harbor Bay assumptions'!B13="",'Harbor Bay monthly P&L and cash'!I25="")))),"",'Harbor Bay monthly P&L and cash'!H31+'Harbor Bay monthly P&L and cash'!I25) -> 184250.97 | J31: =IF(IF(IF(IFERROR('Harbor Bay assumptions'!B13=""=TRUE,FALSE),TRUE,IF(IFERROR('Harbor Bay monthly P&L and cash'!J25=""=TRUE,FALSE),TRUE,OR('Harbor Bay assumptions'!B13="",'Harbor Bay monthly P&L and cash'!J25="")))="",FALSE,IF(IFERROR('Harbor Bay assumptions'!B13=""=TRUE,FALSE),TRUE,IF(IFERROR('Harbor Bay monthly P&L and cash'!J25=""=TRUE,FALSE),TRUE,OR('Harbor Bay assumptions'!B13="",'Harbor Bay monthly P&L and cash'!J25="")))),"",'Harbor Bay monthly P&L and cash'!I31+'Harbor Bay monthly P&L and cash'!J25) -> 203532.34 | K31: =IF(IF(IF(IFERROR('Harbor Bay assumptions'!B13=""=TRUE,FALSE),TRUE,IF(IFERROR('Harbor Bay monthly P&L and cash'!K25=""=TRUE,FALSE),TRUE,OR('Harbor Bay assumptions'!B13="",'Harbor Bay monthly P&L and cash'!K25="")))="",FALSE,IF(IFERROR('Harbor Bay assumptions'!B13=""=TRUE,FALSE),TRUE,IF(IFERROR('Harbor Bay monthly P&L and cash'!K25=""=TRUE,FALSE),TRUE,OR('Harbor Bay assumptions'!B13="",'Harbor Bay monthly P&L and cash'!K25="")))),"",'Harbor Bay monthly P&L and cash'!J31+'Harbor Bay monthly P&L and cash'!K25) -> 222813.71 | L31: =IF(IF(IF(IFERROR('Harbor Bay assumptions'!B13=""=TRUE,FALSE),TRUE,IF(IFERROR('Harbor Bay monthly P&L and cash'!L25=""=TRUE,FALSE),TRUE,OR('Harbor Bay assumptions'!B13="",'Harbor Bay monthly P&L and cash'!L25="")))="",FALSE,IF(IFERROR('Harbor Bay assumptions'!B13=""=TRUE,FALSE),TRUE,IF(IFERROR('Harbor Bay monthly P&L and cash'!L25=""=TRUE,FALSE),TRUE,OR('Harbor Bay assumptions'!B13="",'Harbor Bay monthly P&L and cash'!L25="")))),"",'Harbor Bay monthly P&L and cash'!K31+'Harbor Bay monthly P&L and cash'!L25) -> 242095.08 | M31: =IF(IF(IF(IFERROR('Harbor Bay assumptions'!B13=""=TRUE,FALSE),TRUE,IF(IFERROR('Harbor Bay monthly P&L and cash'!M25=""=TRUE,FALSE),TRUE,OR('Harbor Bay assumptions'!B13="",'Harbor Bay monthly P&L and cash'!M25="")))="",FALSE,IF(IFERROR('Harbor Bay assumptions'!B13=""=TRUE,FALSE),TRUE,IF(IFERROR('Harbor Bay monthly P&L and cash'!M25=""=TRUE,FALSE),TRUE,OR('Harbor Bay assumptions'!B13="",'Harbor Bay monthly P&L and cash'!M25="")))),"",'Harbor Bay monthly P&L and cash'!L31+'Harbor Bay monthly P&L and cash'!M25) -> 261376.46 | N31: =IF(IF(IF(IFERROR('Harbor Bay assumptions'!B13=""=TRUE,FALSE),TRUE,IF(IFERROR('Harbor Bay monthly P&L and cash'!N25=""=TRUE,FALSE),TRUE,OR('Harbor Bay assumptions'!B13="",'Harbor Bay monthly P&L and cash'!N25="")))="",FALSE,IF(IFERROR('Harbor Bay assumptions'!B13=""=TRUE,FALSE),TRUE,IF(IFERROR('Harbor Bay monthly P&L and cash'!N25=""=TRUE,FALSE),TRUE,OR('Harbor Bay assumptions'!B13="",'Harbor Bay monthly P&L and cash'!N25="")))),"",'Harbor Bay monthly P&L and cash'!M31+'Harbor Bay monthly P&L and cash'!N25) -> 280657.83 | O31: =IF(IF(IF(IFERROR('Harbor Bay assumptions'!B13=""=TRUE,FALSE),TRUE,IF(IFERROR('Harbor Bay monthly P&L and cash'!O25=""=TRUE,FALSE),TRUE,OR('Harbor Bay assumptions'!B13="",'Harbor Bay monthly P&L and cash'!O25="")))="",FALSE,IF(IFERROR('Harbor Bay assumptions'!B13=""=TRUE,FALSE),TRUE,IF(IFERROR('Harbor Bay monthly P&L and cash'!O25=""=TRUE,FALSE),TRUE,OR('Harbor Bay assumptions'!B13="",'Harbor Bay monthly P&L and cash'!O25="")))),"",'Harbor Bay monthly P&L and cash'!N31+'Harbor Bay monthly P&L and cash'!O25) -> 299939.2 | P31: =IF(IF(IF(IFERROR('Harbor Bay assumptions'!B13=""=TRUE,FALSE),TRUE,IF(IFERROR('Harbor Bay monthly P&L and cash'!P25=""=TRUE,FALSE),TRUE,OR('Harbor Bay assumptions'!B13="",'Harbor Bay monthly P&L and cash'!P25="")))="",FALSE,IF(IFERROR('Harbor Bay assumptions'!B13=""=TRUE,FALSE),TRUE,IF(IFERROR('Harbor Bay monthly P&L and cash'!P25=""=TRUE,FALSE),TRUE,OR('Harbor Bay assumptions'!B13="",'Harbor Bay monthly P&L and cash'!P25="")))),"",'Harbor Bay monthly P&L and cash'!O31+'Harbor Bay monthly P&L and cash'!P25) -> 319220.57
A32: Harbor Bay | B32: =IF(IF(IF(IFERROR('Harbor Bay assumptions'!B13=""=TRUE,FALSE),TRUE,IF(IFERROR('Harbor Bay monthly P&L and cash'!B26=""=TRUE,FALSE),TRUE,OR('Harbor Bay assumptions'!B13="",'Harbor Bay monthly P&L and cash'!B26="")))="",FALSE,IF(IFERROR('Harbor Bay assumptions'!B13=""=TRUE,FALSE),TRUE,IF(IFERROR('Harbor Bay monthly P&L and cash'!B26=""=TRUE,FALSE),TRUE,OR('Harbor Bay assumptions'!B13="",'Harbor Bay monthly P&L and cash'!B26="")))),"",'Model inputs'!D17+'Harbor Bay monthly P&L and cash'!B26) -> 49281.371 | C32: =IF(IF(IF(IFERROR('Harbor Bay assumptions'!B13=""=TRUE,FALSE),TRUE,IF(IFERROR('Harbor Bay monthly P&L and cash'!C26=""=TRUE,FALSE),TRUE,OR('Harbor Bay assumptions'!B13="",'Harbor Bay monthly P&L and cash'!C26="")))="",FALSE,IF(IFERROR('Harbor Bay assumptions'!B13=""=TRUE,FALSE),TRUE,IF(IFERROR('Harbor Bay monthly P&L and cash'!C26=""=TRUE,FALSE),TRUE,OR('Harbor Bay assumptions'!B13="",'Harbor Bay monthly P&L and cash'!C26="")))),"",'Harbor Bay monthly P&L and cash'!B32+'Harbor Bay monthly P&L and cash'!C26) -> 68562.743 | D32: =IF(IF(IF(IFERROR('Harbor Bay assumptions'!B13=""=TRUE,FALSE),TRUE,IF(IFERROR('Harbor Bay monthly P&L and cash'!D26=""=TRUE,FALSE),TRUE,OR('Harbor Bay assumptions'!B13="",'Harbor Bay monthly P&L and cash'!D26="")))="",FALSE,IF(IFERROR('Harbor Bay assumptions'!B13=""=TRUE,FALSE),TRUE,IF(IFERROR('Harbor Bay monthly P&L and cash'!D26=""=TRUE,FALSE),TRUE,OR('Harbor Bay assumptions'!B13="",'Harbor Bay monthly P&L and cash'!D26="")))),"",'Harbor Bay monthly P&L and cash'!C32+'Harbor Bay monthly P&L and cash'!D26) -> 87844.114 | E32: =IF(IF(IF(IFERROR('Harbor Bay assumptions'!B13=""=TRUE,FALSE),TRUE,IF(IFERROR('Harbor Bay monthly P&L and cash'!E26=""=TRUE,FALSE),TRUE,OR('Harbor Bay assumptions'!B13="",'Harbor Bay monthly P&L and cash'!E26="")))="",FALSE,IF(IFERROR('Harbor Bay assumptions'!B13=""=TRUE,FALSE),TRUE,IF(IFERROR('Harbor Bay monthly P&L and cash'!E26=""=TRUE,FALSE),TRUE,OR('Harbor Bay assumptions'!B13="",'Harbor Bay monthly P&L and cash'!E26="")))),"",'Harbor Bay monthly P&L and cash'!D32+'Harbor Bay monthly P&L and cash'!E26) -> 107125.49 | F32: =IF(IF(IF(IFERROR('Harbor Bay assumptions'!B13=""=TRUE,FALSE),TRUE,IF(IFERROR('Harbor Bay monthly P&L and cash'!F26=""=TRUE,FALSE),TRUE,OR('Harbor Bay assumptions'!B13="",'Harbor Bay monthly P&L and cash'!F26="")))="",FALSE,IF(IFERROR('Harbor Bay assumptions'!B13=""=TRUE,FALSE),TRUE,IF(IFERROR('Harbor Bay monthly P&L and cash'!F26=""=TRUE,FALSE),TRUE,OR('Harbor Bay assumptions'!B13="",'Harbor Bay monthly P&L and cash'!F26="")))),"",'Harbor Bay monthly P&L and cash'!E32+'Harbor Bay monthly P&L and cash'!F26) -> 126406.86 | G32: =IF(IF(IF(IFERROR('Harbor Bay assumptions'!B13=""=TRUE,FALSE),TRUE,IF(IFERROR('Harbor Bay monthly P&L and cash'!G26=""=TRUE,FALSE),TRUE,OR('Harbor Bay assumptions'!B13="",'Harbor Bay monthly P&L and cash'!G26="")))="",FALSE,IF(IFERROR('Harbor Bay assumptions'!B13=""=TRUE,FALSE),TRUE,IF(IFERROR('Harbor Bay monthly P&L and cash'!G26=""=TRUE,FALSE),TRUE,OR('Harbor Bay assumptions'!B13="",'Harbor Bay monthly P&L and cash'!G26="")))),"",'Harbor Bay monthly P&L and cash'!F32+'Harbor Bay monthly P&L and cash'!G26) -> 145688.23 | H32: =IF(IF(IF(IFERROR('Harbor Bay assumptions'!B13=""=TRUE,FALSE),TRUE,IF(IFERROR('Harbor Bay monthly P&L and cash'!H26=""=TRUE,FALSE),TRUE,OR('Harbor Bay assumptions'!B13="",'Harbor Bay monthly P&L and cash'!H26="")))="",FALSE,IF(IFERROR('Harbor Bay assumptions'!B13=""=TRUE,FALSE),TRUE,IF(IFERROR('Harbor Bay monthly P&L and cash'!H26=""=TRUE,FALSE),TRUE,OR('Harbor Bay assumptions'!B13="",'Harbor Bay monthly P&L and cash'!H26="")))),"",'Harbor Bay monthly P&L and cash'!G32+'Harbor Bay monthly P&L and cash'!H26) -> 164969.6 | I32: =IF(IF(IF(IFERROR('Harbor Bay assumptions'!B13=""=TRUE,FALSE),TRUE,IF(IFERROR('Harbor Bay monthly P&L and cash'!I26=""=TRUE,FALSE),TRUE,OR('Harbor Bay assumptions'!B13="",'Harbor Bay monthly P&L and cash'!I26="")))="",FALSE,IF(IFERROR('Harbor Bay assumptions'!B13=""=TRUE,FALSE),TRUE,IF(IFERROR('Harbor Bay monthly P&L and cash'!I26=""=TRUE,FALSE),TRUE,OR('Harbor Bay assumptions'!B13="",'Harbor Bay monthly P&L and cash'!I26="")))),"",'Harbor Bay monthly P&L and cash'!H32+'Harbor Bay monthly P&L and cash'!I26) -> 184250.97 | J32: =IF(IF(IF(IFERROR('Harbor Bay assumptions'!B13=""=TRUE,FALSE),TRUE,IF(IFERROR('Harbor Bay monthly P&L and cash'!J26=""=TRUE,FALSE),TRUE,OR('Harbor Bay assumptions'!B13="",'Harbor Bay monthly P&L and cash'!J26="")))="",FALSE,IF(IFERROR('Harbor Bay assumptions'!B13=""=TRUE,FALSE),TRUE,IF(IFERROR('Harbor Bay monthly P&L and cash'!J26=""=TRUE,FALSE),TRUE,OR('Harbor Bay assumptions'!B13="",'Harbor Bay monthly P&L and cash'!J26="")))),"",'Harbor Bay monthly P&L and cash'!I32+'Harbor Bay monthly P&L and cash'!J26) -> 203532.34 | K32: =IF(IF(IF(IFERROR('Harbor Bay assumptions'!B13=""=TRUE,FALSE),TRUE,IF(IFERROR('Harbor Bay monthly P&L and cash'!K26=""=TRUE,FALSE),TRUE,OR('Harbor Bay assumptions'!B13="",'Harbor Bay monthly P&L and cash'!K26="")))="",FALSE,IF(IFERROR('Harbor Bay assumptions'!B13=""=TRUE,FALSE),TRUE,IF(IFERROR('Harbor Bay monthly P&L and cash'!K26=""=TRUE,FALSE),TRUE,OR('Harbor Bay assumptions'!B13="",'Harbor Bay monthly P&L and cash'!K26="")))),"",'Harbor Bay monthly P&L and cash'!J32+'Harbor Bay monthly P&L and cash'!K26) -> 222813.71 | L32: =IF(IF(IF(IFERROR('Harbor Bay assumptions'!B13=""=TRUE,FALSE),TRUE,IF(IFERROR('Harbor Bay monthly P&L and cash'!L26=""=TRUE,FALSE),TRUE,OR('Harbor Bay assumptions'!B13="",'Harbor Bay monthly P&L and cash'!L26="")))="",FALSE,IF(IFERROR('Harbor Bay assumptions'!B13=""=TRUE,FALSE),TRUE,IF(IFERROR('Harbor Bay monthly P&L and cash'!L26=""=TRUE,FALSE),TRUE,OR('Harbor Bay assumptions'!B13="",'Harbor Bay monthly P&L and cash'!L26="")))),"",'Harbor Bay monthly P&L and cash'!K32+'Harbor Bay monthly P&L and cash'!L26) -> 242095.08 | M32: =IF(IF(IF(IFERROR('Harbor Bay assumptions'!B13=""=TRUE,FALSE),TRUE,IF(IFERROR('Harbor Bay monthly P&L and cash'!M26=""=TRUE,FALSE),TRUE,OR('Harbor Bay assumptions'!B13="",'Harbor Bay monthly P&L and cash'!M26="")))="",FALSE,IF(IFERROR('Harbor Bay assumptions'!B13=""=TRUE,FALSE),TRUE,IF(IFERROR('Harbor Bay monthly P&L and cash'!M26=""=TRUE,FALSE),TRUE,OR('Harbor Bay assumptions'!B13="",'Harbor Bay monthly P&L and cash'!M26="")))),"",'Harbor Bay monthly P&L and cash'!L32+'Harbor Bay monthly P&L and cash'!M26) -> 261376.46 | N32: =IF(IF(IF(IFERROR('Harbor Bay assumptions'!B13=""=TRUE,FALSE),TRUE,IF(IFERROR('Harbor Bay monthly P&L and cash'!N26=""=TRUE,FALSE),TRUE,OR('Harbor Bay assumptions'!B13="",'Harbor Bay monthly P&L and cash'!N26="")))="",FALSE,IF(IFERROR('Harbor Bay assumptions'!B13=""=TRUE,FALSE),TRUE,IF(IFERROR('Harbor Bay monthly P&L and cash'!N26=""=TRUE,FALSE),TRUE,OR('Harbor Bay assumptions'!B13="",'Harbor Bay monthly P&L and cash'!N26="")))),"",'Harbor Bay monthly P&L and cash'!M32+'Harbor Bay monthly P&L and cash'!N26) -> 280657.83 | O32: =IF(IF(IF(IFERROR('Harbor Bay assumptions'!B13=""=TRUE,FALSE),TRUE,IF(IFERROR('Harbor Bay monthly P&L and cash'!O26=""=TRUE,FALSE),TRUE,OR('Harbor Bay assumptions'!B13="",'Harbor Bay monthly P&L and cash'!O26="")))="",FALSE,IF(IFERROR('Harbor Bay assumptions'!B13=""=TRUE,FALSE),TRUE,IF(IFERROR('Harbor Bay monthly P&L and cash'!O26=""=TRUE,FALSE),TRUE,OR('Harbor Bay assumptions'!B13="",'Harbor Bay monthly P&L and cash'!O26="")))),"",'Harbor Bay monthly P&L and cash'!N32+'Harbor Bay monthly P&L and cash'!O26) -> 299939.2 | P32: =IF(IF(IF(IFERROR('Harbor Bay assumptions'!B13=""=TRUE,FALSE),TRUE,IF(IFERROR('Harbor Bay monthly P&L and cash'!P26=""=TRUE,FALSE),TRUE,OR('Harbor Bay assumptions'!B13="",'Harbor Bay monthly P&L and cash'!P26="")))="",FALSE,IF(IFERROR('Harbor Bay assumptions'!B13=""=TRUE,FALSE),TRUE,IF(IFERROR('Harbor Bay monthly P&L and cash'!P26=""=TRUE,FALSE),TRUE,OR('Harbor Bay assumptions'!B13="",'Harbor Bay monthly P&L and cash'!P26="")))),"",'Harbor Bay monthly P&L and cash'!O32+'Harbor Bay monthly P&L and cash'!P26) -> 319220.57
A33: Runway (months, loss cases only) | B33: =IF(IF(IF(IFERROR('Harbor Bay monthly P&L and cash'!B25=""=TRUE,FALSE),TRUE,IF(IFERROR('Harbor Bay monthly P&L and cash'!B31=""=TRUE,FALSE),TRUE,OR('Harbor Bay monthly P&L and cash'!B25="",'Harbor Bay monthly P&L and cash'!B31="")))="",FALSE,IF(IFERROR('Harbor Bay monthly P&L and cash'!B25=""=TRUE,FALSE),TRUE,IF(IFERROR('Harbor Bay monthly P&L and cash'!B31=""=TRUE,FALSE),TRUE,OR('Harbor Bay monthly P&L and cash'!B25="",'Harbor Bay monthly P&L and cash'!B31="")))),"",IFERROR(IF(IF(IF(ISERROR('Harbor Bay monthly P&L and cash'!B25<0),'Harbor Bay monthly P&L and cash'!B25<0,IF('Harbor Bay monthly P&L and cash'!B25="","",'Harbor Bay monthly P&L and cash'!B25<0))="",FALSE,IF(ISERROR('Harbor Bay monthly P&L and cash'!B25<0),'Harbor Bay monthly P&L and cash'!B25<0,IF('Harbor Bay monthly P&L and cash'!B25="","",'Harbor Bay monthly P&L and cash'!B25<0))),MAX('Harbor Bay monthly P&L and cash'!B31/(0-'Harbor Bay monthly P&L and cash'!B25),0),""),"")) | C33: =IF(IF(IF(IFERROR('Harbor Bay monthly P&L and cash'!C25=""=TRUE,FALSE),TRUE,IF(IFERROR('Harbor Bay monthly P&L and cash'!C31=""=TRUE,FALSE),TRUE,OR('Harbor Bay monthly P&L and cash'!C25="",'Harbor Bay monthly P&L and cash'!C31="")))="",FALSE,IF(IFERROR('Harbor Bay monthly P&L and cash'!C25=""=TRUE,FALSE),TRUE,IF(IFERROR('Harbor Bay monthly P&L and cash'!C31=""=TRUE,FALSE),TRUE,OR('Harbor Bay monthly P&L and cash'!C25="",'Harbor Bay monthly P&L and cash'!C31="")))),"",IFERROR(IF(IF(IF(ISERROR('Harbor Bay monthly P&L and cash'!C25<0),'Harbor Bay monthly P&L and cash'!C25<0,IF('Harbor Bay monthly P&L and cash'!C25="","",'Harbor Bay monthly P&L and cash'!C25<0))="",FALSE,IF(ISERROR('Harbor Bay monthly P&L and cash'!C25<0),'Harbor Bay monthly P&L and cash'!C25<0,IF('Harbor Bay monthly P&L and cash'!C25="","",'Harbor Bay monthly P&L and cash'!C25<0))),MAX('Harbor Bay monthly P&L and cash'!C31/(0-'Harbor Bay monthly P&L and cash'!C25),0),""),"")) | D33: =IF(IF(IF(IFERROR('Harbor Bay monthly P&L and cash'!D25=""=TRUE,FALSE),TRUE,IF(IFERROR('Harbor Bay monthly P&L and cash'!D31=""=TRUE,FALSE),TRUE,OR('Harbor Bay monthly P&L and cash'!D25="",'Harbor Bay monthly P&L and cash'!D31="")))="",FALSE,IF(IFERROR('Harbor Bay monthly P&L and cash'!D25=""=TRUE,FALSE),TRUE,IF(IFERROR('Harbor Bay monthly P&L and cash'!D31=""=TRUE,FALSE),TRUE,OR('Harbor Bay monthly P&L and cash'!D25="",'Harbor Bay monthly P&L and cash'!D31="")))),"",IFERROR(IF(IF(IF(ISERROR('Harbor Bay monthly P&L and cash'!D25<0),'Harbor Bay monthly P&L and cash'!D25<0,IF('Harbor Bay monthly P&L and cash'!D25="","",'Harbor Bay monthly P&L and cash'!D25<0))="",FALSE,IF(ISERROR('Harbor Bay monthly P&L and cash'!D25<0),'Harbor Bay monthly P&L and cash'!D25<0,IF('Harbor Bay monthly P&L and cash'!D25="","",'Harbor Bay monthly P&L and cash'!D25<0))),MAX('Harbor Bay monthly P&L and cash'!D31/(0-'Harbor Bay monthly P&L and cash'!D25),0),""),"")) | E33: =IF(IF(IF(IFERROR('Harbor Bay monthly P&L and cash'!E25=""=TRUE,FALSE),TRUE,IF(IFERROR('Harbor Bay monthly P&L and cash'!E31=""=TRUE,FALSE),TRUE,OR('Harbor Bay monthly P&L and cash'!E25="",'Harbor Bay monthly P&L and cash'!E31="")))="",FALSE,IF(IFERROR('Harbor Bay monthly P&L and cash'!E25=""=TRUE,FALSE),TRUE,IF(IFERROR('Harbor Bay monthly P&L and cash'!E31=""=TRUE,FALSE),TRUE,OR('Harbor Bay monthly P&L and cash'!E25="",'Harbor Bay monthly P&L and cash'!E31="")))),"",IFERROR(IF(IF(IF(ISERROR('Harbor Bay monthly P&L and cash'!E25<0),'Harbor Bay monthly P&L and cash'!E25<0,IF('Harbor Bay monthly P&L and cash'!E25="","",'Harbor Bay monthly P&L and cash'!E25<0))="",FALSE,IF(ISERROR('Harbor Bay monthly P&L and cash'!E25<0),'Harbor Bay monthly P&L and cash'!E25<0,IF('Harbor Bay monthly P&L and cash'!E25="","",'Harbor Bay monthly P&L and cash'!E25<0))),MAX('Harbor Bay monthly P&L and cash'!E31/(0-'Harbor Bay monthly P&L and cash'!E25),0),""),"")) | F33: =IF(IF(IF(IFERROR('Harbor Bay monthly P&L and cash'!F25=""=TRUE,FALSE),TRUE,IF(IFERROR('Harbor Bay monthly P&L and cash'!F31=""=TRUE,FALSE),TRUE,OR('Harbor Bay monthly P&L and cash'!F25="",'Harbor Bay monthly P&L and cash'!F31="")))="",FALSE,IF(IFERROR('Harbor Bay monthly P&L and cash'!F25=""=TRUE,FALSE),TRUE,IF(IFERROR('Harbor Bay monthly P&L and cash'!F31=""=TRUE,FALSE),TRUE,OR('Harbor Bay monthly P&L and cash'!F25="",'Harbor Bay monthly P&L and cash'!F31="")))),"",IFERROR(IF(IF(IF(ISERROR('Harbor Bay monthly P&L and cash'!F25<0),'Harbor Bay monthly P&L and cash'!F25<0,IF('Harbor Bay monthly P&L and cash'!F25="","",'Harbor Bay monthly P&L and cash'!F25<0))="",FALSE,IF(ISERROR('Harbor Bay monthly P&L and cash'!F25<0),'Harbor Bay monthly P&L and cash'!F25<0,IF('Harbor Bay monthly P&L and cash'!F25="","",'Harbor Bay monthly P&L and cash'!F25<0))),MAX('Harbor Bay monthly P&L and cash'!F31/(0-'Harbor Bay monthly P&L and cash'!F25),0),""),"")) | G33: =IF(IF(IF(IFERROR('Harbor Bay monthly P&L and cash'!G25=""=TRUE,FALSE),TRUE,IF(IFERROR('Harbor Bay monthly P&L and cash'!G31=""=TRUE,FALSE),TRUE,OR('Harbor Bay monthly P&L and cash'!G25="",'Harbor Bay monthly P&L and cash'!G31="")))="",FALSE,IF(IFERROR('Harbor Bay monthly P&L and cash'!G25=""=TRUE,FALSE),TRUE,IF(IFERROR('Harbor Bay monthly P&L and cash'!G31=""=TRUE,FALSE),TRUE,OR('Harbor Bay monthly P&L and cash'!G25="",'Harbor Bay monthly P&L and cash'!G31="")))),"",IFERROR(IF(IF(IF(ISERROR('Harbor Bay monthly P&L and cash'!G25<0),'Harbor Bay monthly P&L and cash'!G25<0,IF('Harbor Bay monthly P&L and cash'!G25="","",'Harbor Bay monthly P&L and cash'!G25<0))="",FALSE,IF(ISERROR('Harbor Bay monthly P&L and cash'!G25<0),'Harbor Bay monthly P&L and cash'!G25<0,IF('Harbor Bay monthly P&L and cash'!G25="","",'Harbor Bay monthly P&L and cash'!G25<0))),MAX('Harbor Bay monthly P&L and cash'!G31/(0-'Harbor Bay monthly P&L and cash'!G25),0),""),"")) | H33: =IF(IF(IF(IFERROR('Harbor Bay monthly P&L and cash'!H25=""=TRUE,FALSE),TRUE,IF(IFERROR('Harbor Bay monthly P&L and cash'!H31=""=TRUE,FALSE),TRUE,OR('Harbor Bay monthly P&L and cash'!H25="",'Harbor Bay monthly P&L and cash'!H31="")))="",FALSE,IF(IFERROR('Harbor Bay monthly P&L and cash'!H25=""=TRUE,FALSE),TRUE,IF(IFERROR('Harbor Bay monthly P&L and cash'!H31=""=TRUE,FALSE),TRUE,OR('Harbor Bay monthly P&L and cash'!H25="",'Harbor Bay monthly P&L and cash'!H31="")))),"",IFERROR(IF(IF(IF(ISERROR('Harbor Bay monthly P&L and cash'!H25<0),'Harbor Bay monthly P&L and cash'!H25<0,IF('Harbor Bay monthly P&L and cash'!H25="","",'Harbor Bay monthly P&L and cash'!H25<0))="",FALSE,IF(ISERROR('Harbor Bay monthly P&L and cash'!H25<0),'Harbor Bay monthly P&L and cash'!H25<0,IF('Harbor Bay monthly P&L and cash'!H25="","",'Harbor Bay monthly P&L and cash'!H25<0))),MAX('Harbor Bay monthly P&L and cash'!H31/(0-'Harbor Bay monthly P&L and cash'!H25),0),""),"")) | I33: =IF(IF(IF(IFERROR('Harbor Bay monthly P&L and cash'!I25=""=TRUE,FALSE),TRUE,IF(IFERROR('Harbor Bay monthly P&L and cash'!I31=""=TRUE,FALSE),TRUE,OR('Harbor Bay monthly P&L and cash'!I25="",'Harbor Bay monthly P&L and cash'!I31="")))="",FALSE,IF(IFERROR('Harbor Bay monthly P&L and cash'!I25=""=TRUE,FALSE),TRUE,IF(IFERROR('Harbor Bay monthly P&L and cash'!I31=""=TRUE,FALSE),TRUE,OR('Harbor Bay monthly P&L and cash'!I25="",'Harbor Bay monthly P&L and cash'!I31="")))),"",IFERROR(IF(IF(IF(ISERROR('Harbor Bay monthly P&L and cash'!I25<0),'Harbor Bay monthly P&L and cash'!I25<0,IF('Harbor Bay monthly P&L and cash'!I25="","",'Harbor Bay monthly P&L and cash'!I25<0))="",FALSE,IF(ISERROR('Harbor Bay monthly P&L and cash'!I25<0),'Harbor Bay monthly P&L and cash'!I25<0,IF('Harbor Bay monthly P&L and cash'!I25="","",'Harbor Bay monthly P&L and cash'!I25<0))),MAX('Harbor Bay monthly P&L and cash'!I31/(0-'Harbor Bay monthly P&L and cash'!I25),0),""),"")) | ... P33: =IF(IF(IF(IFERROR('Harbor Bay monthly P&L and cash'!P25=""=TRUE,FALSE),TRUE,IF(IFERROR('Harbor Bay monthly P&L and cash'!P31=""=TRUE,FALSE),TRUE,OR('Harbor Bay monthly P&L and cash'!P25="",'Harbor Bay monthly P&L and cash'!P31="")))="",FALSE,IF(IFERROR('Harbor Bay monthly P&L and cash'!P25=""=TRUE,FALSE),TRUE,IF(IFERROR('Harbor Bay monthly P&L and cash'!P31=""=TRUE,FALSE),TRUE,OR('Harbor Bay monthly P&L and cash'!P25="",'Harbor Bay monthly P&L and cash'!P31="")))),"",IFERROR(IF(IF(IF(ISERROR('Harbor Bay monthly P&L and cash'!P25<0),'Harbor Bay monthly P&L and cash'!P25<0,IF('Harbor Bay monthly P&L and cash'!P25="","",'Harbor Bay monthly P&L and cash'!P25<0))="",FALSE,IF(ISERROR('Harbor Bay monthly P&L and cash'!P25<0),'Harbor Bay monthly P&L and cash'!P25<0,IF('Harbor Bay monthly P&L and cash'!P25="","",'Harbor Bay monthly P&L and cash'!P25<0))),MAX('Harbor Bay monthly P&L and cash'!P31/(0-'Harbor Bay monthly P&L and cash'!P25),0),""),""))
